Workbook
Name CAJA_DE_CAPTACION: #REF!
Name CAJA_DE_CAPTACION: #REF!
Name CAJA_DE_CAPTACION: #REF!
Name LIN_DISTR_ELECT.: '[1]PRES 1'!#REF!
Name LIN_DISTR_ELECT.: #REF!
Name LIN_DISTR_ELECT.: '[1]PRES 1'!#REF!
Name LIN_DISTR_ELECT.: #REF!
Name SUBEST_ELECTR: '[1]PRES 1'!#REF!
Name SUBEST_ELECTR: #REF!
Name SUBEST_ELECTR: '[1]PRES 1'!#REF!
Name SUBEST_ELECTR: #REF!

Sheet DATOS
C1: ESTUDIO FINANCIERO
C3: DATOS ADICIONALES
C5: Inflación | D5: 0.09 | E5: Anual
C6: Incremento salarial | D6: 0.12 | E6: Anual
C7: Incremento volumen | D7: 0.03 | E7: cada 3 meses durante el primer año
C8: Incremento precio unitario de venta | D8: 0.09 | E8: A partir del segundo semestre del primer año y durante los sig años
C10: Depreciación en línea recta | E10: LISR
C12: Amortización de la deuda de acuerdo a la
C13: dependencia que otorgará el financiamiento

Sheet CUADRO DE INVERSION
B3: TAQUERIA TAKIRIN "LA CHIMENEA"
B8: CONCEPTO | C8: FIRA | D8: TAKIRIN | E8: TOTAL
B9: Cap. Trabajo | C9: 0 | D9: 0 | E9: =SUM(C9:D9) -> 0
B10: Inv. Fija | C10: =G32 -> 1127676.7 | D10: =H32 -> 820000 | E10: =SUM(C10:D10) -> 1947676.7
B11: Inv. Diferida | C11: =F37 -> 312151.51 | D11: 0 | E11: =SUM(C11:D11) -> 312151.51
B12: Total | C12: =SUM(C9:C11) -> 1439828.2 | D12: =SUM(D9:D11) -> 820000 | E12: =SUM(E9:E11) -> 2259828.2
B13: % | C13: =C12/E12 -> 0.63714056 | D13: =D12/E12 -> 0.36285944 | E13: =SUM(C13:D13) -> 1
B16: CAPITAL DE TRABAJO | C16: CANTIDAD | D16: UNIDAD | E16: COSTO | F16: TOTAL | G16: FIRA | H16: TAKIRIN
B17: INVERSION FIJA
B18: EDIFICIO | C18: 1 | D18: UNIDAD | E18: 604576.32 | F18: =C18*E18 -> 604576.32 | G18: 604576.32
B19: TERRENO | C19: 1 | D19: LOTE | E19: 820000 | F19: =C19*E19 -> 820000 | H19: =F19 -> 820000
B20: MAQUINARIA DE EMPAQUETADO | C20: 2 | D20: UNIDADES | E20: 59908.16 | F20: =C20*E20 -> 119816.32 | G20: =F20 -> 119816.32
B21: PLANCHAS | C21: 2 | D21: UNIDADES | E21: 42380 | F21: =C21*E21 -> 84760 | G21: =F21 -> 84760
B22: TRAMPA DE ACEITE | C22: 1 | D22: UNIDAD | E22: 2 | F22: 8131.73 | G22: =F22 -> 8131.73
B23: TROMPOS | C23: 2 | D23: UNIDADES | E23: 10944.25 | F23: =C23*E23 -> 21888.5 | G23: =F23 -> 21888.5
B24: CAMPANA | C24: 2 | D24: UNIDADES | E24: 9174.44 | F24: =C24*E24 -> 18348.88 | G24: =F24 -> 18348.88
B25: MOLINOS INDUSTRIALES | C25: 2 | D25: UNIDADES | E25: 29135.72 | F25: =C25*E25 -> 58271.44 | G25: =F25 -> 58271.44
B26: CONGELADORES | C26: 2 | D26: UNIDADES | E26: 17699.28 | F26: =C26*E26 -> 35398.56 | G26: =F26 -> 35398.56
B27: MOBILIARIO | C27: 20 | D27: JUEGOS | E27: 3951 | F27: =C27*E27 -> 79020 | G27: =F27 -> 79020
B28: MESAS DE TRABAJO | C28: 4 | D28: UNIDADES | E28: 21412.46 | F28: =E28*C28 -> 85649.84 | G28: =F28 -> 85649.84
B29: INSTRUMENTOS DE COCINA | C29: 4 | D29: JUEGOS | E29: 906.53 | F29: =E29*C29 -> 3626.12 | G29: =F29 -> 3626.12
B30: EQUIPO DE PUNTO DE VENTA | C30: 1 | D30: UNIDADES | E30: 3599 | F30: =E30 -> 3599 | G30: =F30 -> 3599
B31: EQUIPO DE REGISTRO DE VENTA TERMINAL | C31: 3 | D31: UNIDADES | E31: 1530 | F31: =E31*C31 -> 4590 | G31: =F31 -> 4590
F32: =SUM(F18:F31) -> 1947676.7 | G32: =SUM(G18:G31) -> 1127676.7 | H32: =SUM(H18:H31) -> 820000
B34: INVERSION DIFERIDA
B35: CAPACITACION | C35: 1 | D35: SERVICIO | E35: 20000 | F35: =C35*E35 -> 20000 | G35: =F35 -> 20000
B36: PAGO DE HONORARIOS | C36: 1 | D36: SERVICIO | F36: =F32*0.15 -> 292151.51
F37: =SUM(F35:F36) -> 312151.51 | G37: =SUM(G35) -> 20000 | H37: =SUM(H35) -> 0
C40: CONCEPTO | E40: FIRA | F40: TAKIRIN | G40: TOTAL | H40: %
B41: =E41/E44 -> 0 | C41: Cap. Trab. | E41: =0 -> 0 | F41: 0 | G41: =SUM(E41:F41) -> 0 | H41: =G41/G44 -> 0
C42: Inv. Fija | E42: =G32 -> 1127676.7 | F42: =H32 -> 820000 | G42: =SUM(E42:F42) -> 1947676.7 | H42: =G42/G44 -> 0.86186937
C43: Inv. Diferida | E43: =F37 -> 312151.51 | F43: 0 | G43: =SUM(E43:F43) -> 312151.51 | H43: =G43/G44 -> 0.13813063
B44: =100 -> 100 | C44: Total | E44: =SUM(E41:E43) -> 1439828.2 | F44: =SUM(F41:F43) -> 820000 | G44: =SUM(G41:G43) -> 2259828.2 | H44: 1
C45: % | E45: =(E44/G44)*100 -> 63.714056 | F45: =(F44/G44)*100 -> 36.285944 | G45: 1

Sheet ESTRUCTURA FINANCIERA
A1: ESTUDIO FINANCIERO
A3: ESTRUCTURA FINANCIERA
A5: PROYECTO: Nueva sucursal y maquinaria
A6: SOCIEDAD: Taqueria el takirin "La chimenea"
A7: BENEFICIARIOS:
A9: DESGLOSE DE INVERSION PARA UN AÑO
A10: CONCEPTO | B10: UNIDAD DE | C10: CANTIDAD | D10: PRECIO | E10: COSTO | F10: APORTACION
B11: MEDIDA | D11: UNITARIO | E11: TOTAL | F11: DEPENDENCIA | G11: GRUPO
A12: INVERSION FIJA | F12: FIRA | G12: TAKIRIN
A13: TERRENO | B13: 1 | C13: LOTE | D13: 820000 | E13: =B13*D13 -> 820000 | G13: =E13 -> 820000
A14: MAQUINARIA DE EMPAQUETADO | B14: 2 | C14: UNIDADES | D14: 59908.16 | E14: =B14*D14 -> 119816.32 | F14: =E14 -> 119816.32
A15: PLANCHAS | B15: 2 | C15: UNIDADES | D15: 42380 | E15: =B15*D15 -> 84760 | F15: =E15 -> 84760
A16: TRAMPA DE ACEITE | B16: 1 | C16: UNIDAD | D16: 8131.73 | E16: 8131.73 | F16: =E16 -> 8131.73
A17: TROMPOS | B17: 2 | C17: UNIDADES | D17: 10944.25 | E17: =B17*D17 -> 21888.5 | F17: =E17 -> 21888.5
A18: CAMPANA | B18: 2 | C18: UNIDADES | D18: 9174.44 | E18: =B18*D18 -> 18348.88 | F18: =E18 -> 18348.88
A19: MOLINOS INDUSTRIALES | B19: 2 | C19: UNIDADES | D19: 29135.72 | E19: =B19*D19 -> 58271.44 | F19: =E19 -> 58271.44
A20: CONGELADORES | B20: 2 | C20: UNIDADES | D20: 17699.28 | E20: =B20*D20 -> 35398.56 | F20: =E20 -> 35398.56
A21: MOBILIARIO | B21: 20 | C21: JUEGOS | D21: 3951 | E21: =B21*D21 -> 79020 | F21: =E21 -> 79020
A22: MESAS DE TRABAJO | B22: 4 | C22: UNIDADES | D22: 21412.46 | E22: =D22*B22 -> 85649.84 | F22: =E22 -> 85649.84
A23: INSTRUMENTOS DE COCINA | B23: 4 | C23: JUEGOS | D23: 906.53 | E23: =D23*B23 -> 3626.12 | F23: =E23 -> 3626.12
A24: EQUIPO DE REGISTRO DE VENTA | B24: 1 | C24: UNIDADES | D24: 3599 | E24: =D24 -> 3599 | F24: =E24 -> 3599
A25: EQUIPO DE REGISTRO DE VENTA TERMINAL | B25: 3 | C25: UNIDADES | D25: 1530 | E25: =D25*B25 -> 4590 | F25: =E25 -> 4590
A27: Subtotal | E27: =SUM(E13:E26) -> 1343100.4 | F27: =SUM(F14:F26) -> 523100.39 | G27: =SUM(G13:G26) -> 820000
A28: OBRA CIVIL
A29: Salarios
A30: Arquitecto | B30: 2 | C30: Trabajador | D30: 20000 | E30: =D30*B30 -> 40000 | F30: =E30 -> 40000
A31: Albañiles | B31: 20 | C31: Trabajador | D31: 11100 | E31: =D31*B31 -> 222000 | F31: =E31 -> 222000
A32: Electricistas | B32: 4 | C32: Trabajador | D32: 12100 | E32: =D32*B32 -> 48400 | F32: =E32 -> 48400
A33: Carpinteros | B33: 1 | C33: Trabajador | D33: 12000 | E33: =D33*B33 -> 12000 | F33: =E33 -> 12000
A34: Impuestos
A35: Permisos del Ayuntamiento | B35: 1 | C35: Paquete | D35: 15000.5 | E35: =D35*B35 -> 15000.5 | F35: =E35 -> 15000.5
A36: Impuestos de construcción | B36: 1 | C36: Global | D36: 10000.82 | E36: =D36*B36 -> 10000.82 | F36: =E36 -> 10000.82
A37: Materiales para construcción
A38: Cemento | B38: 91 | C38: Saco | D38: 150 | E38: =D38*B38 -> 13650 | F38: =E38 -> 13650
A39: Tablaroca | B39: 60 | C39: Panel | D39: 209 | E39: =D39*B39 -> 12540 | F39: =E39 -> 12540
A40: Clavos | B40: 50 | C40: Caja | D40: 100 | E40: =D40*B40 -> 5000 | F40: =E40 -> 5000
A41: Cables electricos | B41: 600 | C41: Metro | D41: 30 | E41: =D41*B41 -> 18000 | F41: =E41 -> 18000
A42: Tubos PVC | B42: 207 | C42: Tubo | D42: 30 | E42: =D42*B42 -> 6210 | F42: =E42 -> 6210
A43: Pintura | B43: 40 | C43: Lata | D43: 1000 | E43: =D43*B43 -> 40000 | F43: =E43 -> 40000
A44: Arena | B44: 80 | C44: Saco | D44: 80 | E44: =D44*B44 -> 6400 | F44: =E44 -> 6400
...

Sheet CUADRO DE EGRESOS E INGRESOS
A1: ESTRUCTURA DE INGRESOS Y EGERESOS
A3: SITUACION FINANCIERA ACTUAL Y PROYECTADA
A5: PROYECTO:
A6: SOCIEDAD
A7: BENEFICIARIOS:
B9: FLUJO DE I N G R E S O S Y E G R E S O S
A10: PRIMER AÑO DE INVERSIÓN
A11: C O N C E P T O | C11: 1 MES | D11: 2 MES | E11: 3 MES | F11: 4 MES | G11: 5 MES | H11: 6 MES | I11: 7 MES | J11: 8 MES | K11: 9 MES | L11: 10 MES | M11: 11 MES | N11: 12 MES | O11: TOTAL
A12: INGRESOS POR VENTAS | C12: ='INGRESOS '!B24 -> 1202850 | D12: ='INGRESOS '!C24 -> 1202850 | E12: ='INGRESOS '!D24 -> 1202850 | F12: ='INGRESOS '!E24 -> 1239090 | G12: ='INGRESOS '!F24 -> 1239090 | H12: ='INGRESOS '!G24 -> 1239090 | I12: ='INGRESOS '!H24 -> 1278360 | J12: ='INGRESOS '!I24 -> 1278360 | ... N12: ='INGRESOS '!M24 -> 1320810 | O12: =SUM(C12:N12) -> 15123330
A13: TOTAL DE INGRESOS | C13: =C12 -> 1202850 | D13: =D12 -> 1202850 | E13: =E12 -> 1202850 | F13: =F12 -> 1239090 | G13: =G12 -> 1239090 | H13: =H12 -> 1239090 | I13: =I12 -> 1278360 | J13: =J12 -> 1278360 | ... N13: =N12 -> 1320810 | O13: =SUM(C13:N13) -> 15123330
A14: EGRESOS
A15: VARIABLE | C15: ='COSTOS '!B4 -> 193560 | D15: ='COSTOS '!C4 -> 197431.2 | E15: ='COSTOS '!D4 -> 193482.58 | F15: ='COSTOS '!E4 -> 199287.05 | G15: ='COSTOS '!F4 -> 203272.79 | H15: ='COSTOS '!G4 -> 197174.61 | I15: ='COSTOS '!H4 -> 195202.86 | J15: ='COSTOS '!I4 -> 199106.92 | ... N15: ='COSTOS '!M4 -> 200977.75 | O15: =SUM(C15:N15) -> 2364831.1 | P15: TOTAL DE EGRESOS
A16: FIJOS | C16: ='COSTOS '!B16 -> 207422.46 | D16: ='COSTOS '!C16 -> 207422.46 | E16: ='COSTOS '!D16 -> 207422.46 | F16: ='COSTOS '!E16 -> 207422.46 | G16: ='COSTOS '!F16 -> 207422.46 | H16: ='COSTOS '!G16 -> 207422.46 | I16: ='COSTOS '!H16 -> 207422.46 | J16: ='COSTOS '!I16 -> 207422.46 | ... N16: ='COSTOS '!M16 -> 207422.46 | O16: =SUM(C16:N16) -> 2489069.5 | P16: =O15+O16 -> 4853900.6
A17: SALDO | C17: =C12-(C15+C16) -> 801867.54 | D17: =D12-(D15+D16) -> 797996.34 | E17: =E12-(E15+E16) -> 801944.97 | F17: =F12-(F15+F16) -> 832380.49 | G17: =G12-(G15+G16) -> 828394.75 | H17: =H12-(H15+H16) -> 834492.93 | I17: =I12-(I15+I16) -> 875734.68 | J17: =J12-(J15+J16) -> 871830.62 | ... O17: =O12-(O15+O16) -> 10269429
A18: SALDO ACUMULADO | C18: =+C17 -> 801867.54 | D18: =+D17+C18 -> 1599863.9 | E18: =+E17+D18 -> 2401808.9 | F18: =+F17+E18 -> 3234189.3 | G18: =+G17+F18 -> 4062584.1 | H18: =+H17+G18 -> 4897077 | I18: =+I17+H18 -> 5772811.7 | J18: =+J17+I18 -> 6644642.3 | K18: =+K17+J18 -> 7520455.1 | ... N18: =+N17+M18 -> 10269429 | O18: =+N18 -> 10269429
A22: PROYECCION FINANCIERA ANUAL
A24: SEGUNDO AÑO DE INVERSIÓN
A25: C O N C E P T O | C25: 1 MES | D25: 2 MES | E25: 3 MES | F25: 4 MES | G25: 5 MES | H25: 6 MES | I25: 7 MES | J25: 8 MES | K25: 9 MES | L25: 10 MES | M25: 11 MES | N25: 12 MES | O25: TOTAL
A26: INGRESOS POR VENTAS | C26: ='INGRESOS '!B44 -> 1439682.9 | D26: ='INGRESOS '!C44 -> 1439682.9 | E26: ='INGRESOS '!D44 -> 1439682.9 | F26: ='INGRESOS '!E44 -> 1439682.9 | G26: ='INGRESOS '!F44 -> 1439682.9 | H26: ='INGRESOS '!G44 -> 1439682.9 | I26: ='INGRESOS '!H44 -> 1439682.9 | J26: ='INGRESOS '!I44 -> 1439682.9 | ... N26: ='INGRESOS '!M44 -> 1439682.9 | O26: =SUM(C26:N26) -> 17276195
A27: TOTAL DE INGRESOS | C27: =C26 -> 1439682.9 | D27: =D26 -> 1439682.9 | E27: =E26 -> 1439682.9 | F27: =F26 -> 1439682.9 | G27: =G26 -> 1439682.9 | H27: =H26 -> 1439682.9 | I27: =I26 -> 1439682.9 | J27: =J26 -> 1439682.9 | ... N27: =N26 -> 1439682.9 | O27: =SUM(C27:N27) -> 17276195
K28: 0 | L28: 0 | M28: =+M26*A28 -> 0 | O28: =+J28 -> 0
A29: EGRESOS
A30: VARIABLE | C30: ='COSTOS '!B57 -> 200977.75 | D30: ='COSTOS '!C57 -> 204997.3 | E30: ='COSTOS '!D57 -> 200897.36 | F30: ='COSTOS '!E57 -> 206924.28 | G30: ='COSTOS '!F57 -> 211062.76 | H30: ='COSTOS '!G57 -> 204730.88 | I30: ='COSTOS '!H57 -> 202683.57 | J30: ='COSTOS '!I57 -> 206737.24 | ... O30: ='COSTOS '!N57 -> 2455457.9 | P30: TOTAL DE EGRESOS
A31: FIJOS | C31: ='COSTOS '!B69 -> 207422.46 | D31: ='COSTOS '!C69 -> 207422.46 | E31: ='COSTOS '!D69 -> 207422.46 | F31: ='COSTOS '!E69 -> 207422.46 | G31: ='COSTOS '!F69 -> 207422.46 | H31: ='COSTOS '!G69 -> 207422.46 | I31: ='COSTOS '!H69 -> 207422.46 | J31: ='COSTOS '!I69 -> 207422.46 | ... O31: ='COSTOS '!N69 -> 2489069.5 | P31: =O30+O31 -> 4944527.3
A32: SALDO | C32: =C26-(C30+C31) -> 1031282.7 | D32: =D26-(D30+D31) -> 1027263.1 | E32: =E26-(E30+E31) -> 1031363.1 | F32: =F26-(F30+F31) -> 1025336.2 | G32: =G26-(G30+G31) -> 1021197.7 | H32: =H26-(H30+H31) -> 1027529.6 | I32: =I26-(I30+I31) -> 1029576.9 | J32: =J26-(J30+J31) -> 1025523.2 | ... O32: =O26-(O30+O31) -> 12331667
A33: SALDO ACUMULADO | C33: =+C32 -> 1031282.7 | D33: =+D32+C33 -> 2058545.8 | E33: =+E32+D33 -> 3089908.9 | F33: =+F32+E33 -> 4115245.1 | G33: =+G32+F33 -> 5136442.8 | H33: =+H32+G33 -> 6163972.3 | I33: =+I32+H33 -> 7193549.2 | J33: =+J32+I33 -> 8219072.4 | K33: =+K32+J33 -> 9248730.4 | ... N33: =+N32+M33 -> 12331667 | O33: =+N33 -> 12331667
A35: TERCER AÑO DE INVERSIÓN
A36: C O N C E P T O | C36: 1 MES | D36: 2 MES | E36: 3 MES | F36: 4 MES | G36: 5 MES | H36: 6 MES | I36: 7 MES | J36: 8 MES | K36: 9 MES | L36: 10 MES | M36: 11 MES | N36: 12 MES | O36: TOTAL
A37: INGRESOS POR VENTAS | C37: ='INGRESOS '!B64 -> 1569254.4 | D37: ='INGRESOS '!C64 -> 1569254.4 | E37: ='INGRESOS '!D64 -> 1569254.4 | F37: ='INGRESOS '!E64 -> 1569254.4 | G37: ='INGRESOS '!F64 -> 1569254.4 | H37: ='INGRESOS '!G64 -> 1569254.4 | I37: ='INGRESOS '!H64 -> 1569254.4 | J37: ='INGRESOS '!I64 -> 1569254.4 | ... N37: ='INGRESOS '!M64 -> 1569254.4 | O37: =SUM(C37:N37) -> 18831052
A38: TOTAL DE INGRESOS | C38: =C37 -> 1569254.4 | D38: =D37 -> 1569254.4 | E38: =E37 -> 1569254.4 | F38: =F37 -> 1569254.4 | G38: =G37 -> 1569254.4 | H38: =H37 -> 1569254.4 | I38: =I37 -> 1569254.4 | J38: =J37 -> 1569254.4 | ... N38: =N37 -> 1569254.4 | O38: =SUM(C38:N38) -> 18831052
K39: 0 | L39: 0 | M39: =+M37*A39 -> 0 | O39: =+J39 -> 0
A40: EGRESOS
A41: VARIABLE | C41: ='COSTOS '!B110 -> 208679.76 | D41: ='COSTOS '!C110 -> 212853.36 | E41: ='COSTOS '!D110 -> 208596.29 | F41: ='COSTOS '!E110 -> 214854.18 | G41: ='COSTOS '!F110 -> 219151.26 | H41: ='COSTOS '!G110 -> 212576.72 | I41: ='COSTOS '!H110 -> 210450.96 | J41: ='COSTOS '!I110 -> 214659.98 | ... N41: ='COSTOS '!M110 -> 216676.94 | O41: =SUM(C41:N41) -> 2549557.7 | P41: TOTAL DE EGRESOS
A42: FIJOS | C42: ='COSTOS '!B122 -> 207422.46 | D42: ='COSTOS '!C122 -> 207422.46 | E42: ='COSTOS '!D122 -> 207422.46 | F42: ='COSTOS '!E122 -> 207422.46 | G42: ='COSTOS '!F122 -> 207422.46 | H42: ='COSTOS '!G122 -> 207422.46 | I42: ='COSTOS '!H122 -> 207422.46 | J42: ='COSTOS '!I122 -> 207422.46 | ... O42: ='COSTOS '!N122 -> 2489069.5 | P42: =O41+O42 -> 5038627.2
A43: SALDO | C43: =C37-(C41+C42) -> 1153152.1 | D43: =D37-(D41+D42) -> 1148978.5 | E43: =E37-(E41+E42) -> 1153235.6 | F43: =F37-(F41+F42) -> 1146977.7 | G43: =G37-(G41+G42) -> 1142680.6 | H43: =H37-(H41+H42) -> 1149255.2 | I43: =I37-(I41+I42) -> 1151380.9 | J43: =J37-(J41+J42) -> 1147171.9 | ... O43: =O37-(O41+O42) -> 13792425
A44: SALDO ACUMULADO | C44: =+C43 -> 1153152.1 | D44: =+D43+C44 -> 2302130.7 | E44: =+E43+D44 -> 3455366.3 | F44: =+F43+E44 -> 4602344 | G44: =+G43+F44 -> 5745024.7 | H44: =+H43+G44 -> 6894279.9 | I44: =+I43+H44 -> 8045660.8 | J44: =+J43+I44 -> 9192832.7 | K44: =+K43+J44 -> 10344298 | ... N44: =+N43+M44 -> 13792425 | O44: =+N44 -> 13792425
A46: CUARTO AÑO DE INVERSIÓN
A47: C O N C E P T O | C47: 1 MES | D47: 2 MES | E47: 3 MES | F47: 4 MES | G47: 5 MES | H47: 6 MES | I47: 7 MES | J47: 8 MES | K47: 9 MES | L47: 10 MES | M47: 11 MES | N47: 12 MES | O47: TOTAL
A48: INGRESOS POR VENTAS | C48: ='INGRESOS '!B84 -> 1710487.3 | D48: ='INGRESOS '!C84 -> 1710487.3 | E48: ='INGRESOS '!D84 -> 1710487.3 | F48: ='INGRESOS '!E84 -> 1710487.3 | G48: ='INGRESOS '!F84 -> 1710487.3 | H48: ='INGRESOS '!G84 -> 1710487.3 | I48: ='INGRESOS '!H84 -> 1710487.3 | J48: ='INGRESOS '!I84 -> 1710487.3 | ... N48: ='INGRESOS '!M84 -> 1710487.3 | O48: =SUM(C48:N48) -> 20525847
A49: TOTAL DE INGRESOS | C49: =C48 -> 1710487.3 | D49: =D48 -> 1710487.3 | E49: =E48 -> 1710487.3 | F49: =F48 -> 1710487.3 | G49: =G48 -> 1710487.3 | H49: =H48 -> 1710487.3 | I49: =I48 -> 1710487.3 | J49: =J48 -> 1710487.3 | ... N49: =N48 -> 1710487.3 | O49: =SUM(C49:N49) -> 20525847
...

Sheet PUNTO DE EQUILIBRIO
A1: TAQUERIA TAKIRIN "LA CHIMENEA"
A3: PRECIO UNI | C3: 1135
A4: COSTO VARI UNI | C4: 685.9
A5: COSTO FIJO TOTAL | C5: ='COSTOS '!N16+AMORTIZACIONES!B49 -> 3074192.7
A9: P.E. UNI = | B9: COSTOS FIJOS | E9: = | F9: =C5 -> 3074192.7 | G9: = | H9: =F9 -> 3074192.7 | I9: = | J9: =H9/H10 -> 6845.2299
B10: PRECIO VENTA UNI - COSTO VARIABLE UNI | F10: =C3-C4 -> 449.1 | H10: =F10 -> 449.1
A12: P.E. s/= | B12: COSTOS FIJOS | E12: = | F12: =C5 -> 3074192.7 | G12: = | H12: =F12 -> 3074192.7 | I12: = | J12: =H12 -> 3074192.7 | L12: =J12/J13 -> 7769335.9
B13: 1- | C13: COSTO VARIABLE | F13: =C4 -> 685.9 | H13: =F13/F14 -> 0.60431718 | J13: =1-H13 -> 0.39568282
C14: PRECIO UNI | E14: 1- | F14: =C3 -> 1135
A16: OTRA FORMA | C16: P.E UNI * PRECIO UNI | E16: = | F16: =J9 -> 6845.2299 | G16: * | H16: =C3 -> 1135 | I16: = | J16: =F16*H16 -> 7769335.9
A21: UNIDADES | B21: 0 | C21: 1000 | D21: 2000 | E21: 3000 | F21: 4000 | G21: 5000 | H21: 6000 | I21: 7000 | J21: 8000 | K21: 9000 | L21: 10000 | M21: 11000 | N21: 12000 | O21: 13000 | P21: 14000 | Q21: 15000 | R21: 16000 | S21: 17000 | T21: 18000 | U21: 19000 | V21: 20000 | W21: 21000 | X21: 22000 | Y21: 23000 | Z21: 24000 | AA21: 25000 | AB21: 26000 | AC21: 27000 | AD21: 28000 | AE21: 29000 | AF21: 30000
A22: VENTAS | B22: =B21*$C$3 -> 0 | C22: =C21*$C$3 -> 1135000 | D22: =D21*$C$3 -> 2270000 | E22: =E21*$C$3 -> 3405000 | F22: =F21*$C$3 -> 4540000 | G22: =G21*$C$3 -> 5675000 | H22: =H21*$C$3 -> 6810000 | I22: =I21*$C$3 -> 7945000 | ... AF22: =AF21*$C$3 -> 34050000
A23: COSTOS VARIABLE | B23: =B21*$C$4 -> 0 | C23: =C21*$C$4 -> 685900 | D23: =D21*$C$4 -> 1371800 | E23: =E21*$C$4 -> 2057700 | F23: =F21*$C$4 -> 2743600 | G23: =G21*$C$4 -> 3429500 | H23: =H21*$C$4 -> 4115400 | I23: =I21*$C$4 -> 4801300 | ... AF23: =AF21*$C$4 -> 20577000
A24: MARGEN DE CONTRIBUCION | B24: =B22-B23 -> 0 | C24: =C22-C23 -> 449100 | D24: =D22-D23 -> 898200 | E24: =E22-E23 -> 1347300 | F24: =F22-F23 -> 1796400 | G24: =G22-G23 -> 2245500 | H24: =H22-H23 -> 2694600 | I24: =I22-I23 -> 3143700 | ... AF24: =AF22-AF23 -> 13473000
A25: COSTOS FIJO | B25: =$C$5 -> 3074192.7 | C25: =$C$5 -> 3074192.7 | D25: =$C$5 -> 3074192.7 | E25: =$C$5 -> 3074192.7 | F25: =$C$5 -> 3074192.7 | G25: =$C$5 -> 3074192.7 | H25: =$C$5 -> 3074192.7 | I25: =$C$5 -> 3074192.7 | ... AF25: =$C$5 -> 3074192.7
A26: COSTOS TOTALES | B26: =B25+B23 -> 3074192.7 | C26: =C25+C23 -> 3760092.7 | D26: =D25+D23 -> 4445992.7 | E26: =E25+E23 -> 5131892.7 | F26: =F25+F23 -> 5817792.7 | G26: =G25+G23 -> 6503692.7 | H26: =H25+H23 -> 7189592.7 | I26: =I25+I23 -> 7875492.7 | ... AF26: =AF25+AF23 -> 23651193
A27: UTILIDAD O PERDIDA | B27: =B22-B26 -> -3074192.7 | C27: =C22-C26 -> -2625092.7 | D27: =D22-D26 -> -2175992.7 | E27: =E22-E26 -> -1726892.7 | F27: =F22-F26 -> -1277792.7 | G27: =G22-G26 -> -828692.73 | H27: =H22-H26 -> -379592.73 | I27: =I22-I26 -> 69507.274 | ... AF27: =AF22-AF26 -> 10398807

Sheet M. DE CALCULO DE COSTOS VAR
A1: ESTRUCTURA DE INGRESOS Y EGERESOS
A3: MEMORIAS DE CALCULO COSTOS VARIABLES
A5: PROYECTO:
A6: SOCIEDAD
A7: BENEFICIARIOS:
A10: MEMORIA DE CALCULO MATERIA PRIMA E INSUMOS | G10: MEMORIA DE CALCULO MATERIA PRIMA E INSUMOS | M10: MEMORIA DE CALCULO MATERIA PRIMA E INSUMOS
A11: Taco al pastor | B11: MEDIDA | C11: CANT | D11: C.U. | E11: TOTAL | G11: Taco arabe gigante | H11: MEDIDA | I11: CANT | J11: C.U. | K11: TOTAL | M11: Matahambre | N11: MEDIDA | O11: CANT | P11: C.U. | Q11: TOTAL
A12: Carne de cerdo adobada al pastor | B12: Gramos | C12: 40-50 | D12: 6 | E12: =D12*$F$19 -> 72000 | G12: Carne de cerdo marinada estilo oriental | H12: Gramos | I12: 120 | J12: 50 | K12: =J12*$F$20 -> 45000 | M12: Carne de cerdo adobada al pastor | N12: Gramos | O12: 600 | P12: 70 | Q12: =P12*$F$21 -> 42000
A13: Tortilla de maíz | B13: Pieza | C13: 1 | D13: 0.2 | E13: =D13*$F$19 -> 2400 | G13: Pan árabe (Pita) | H13: Pieza | I13: 2 | J13: 4 | K13: =J13*$F$20 -> 3600 | M13: Tocino | N13: Gramos | O13: 50 | P13: 21 | Q13: =P13*$F$21 -> 12600
A14: Piña | B14: Gramos | C14: 5 | D14: 0.2 | E14: =D14*$F$19 -> 2400 | G14: Subtotal | J14: 54 | K14: =SUM(K12:K13) -> 48600 | L14: $ 100.00 | M14: Tortilla de maíz | N14: Pieza | O14: 18 | P14: 3.6 | Q14: =P14*$F$21 -> 2160
A15: Cebolla | B15: Gramos | C15: 2 | D15: 0.1 | E15: =D15*$F$19 -> 1200 | M15: Chile poblano | N15: Gramos | O15: 50 | P15: 6 | Q15: =P15*$F$21 -> 3600
A16: Cilantro | B16: Gramos | C16: 2 | D16: 0.1 | E16: =D16*$F$19 -> 1200 | K16: =J14/L14 -> #VALUE! | M16: Cebolla | N16: Gramos | O16: 50 | P16: 5 | Q16: =P16*$F$21 -> 3000
A17: Subtotal | D17: 6.6 | E17: =SUM(E12:E16) -> 79200 | F17: 14 | G17: =D17/F17 -> 0.47142857 | M17: Jitomate | N17: Gramos | O17: 50 | P17: 4 | Q17: =P17*$F$21 -> 2400
E18: DIARIO | F18: MENSUAL | M18: Subtotal | P18: $ 109.60 | Q18: =SUM(Q12:Q17) -> 65760 | R18: $ 220.00
D19: TACOS | E19: 400 | F19: =E19*30 -> 12000
D20: ARABE | E20: 30 | F20: =E20*30 -> 900 | Q20: =P18/R18 -> #VALUE!
D21: MATAHAMBRE | E21: 20 | F21: =E21*30 -> 600
A23: MEMORIA DE CALCULO GASTOS INDIRECTOS DE FABRICACION
B24: Porcentaje | C24: Medida | D24: CANT | E24: C.U. | F24: TOTAL MENSUAL
A25: Renta del local | B25: 0.6 | C25: Mes | D25: 1 | E25: 8000 | F25: =E25*0.6 -> 4800
A26: Energía eléctrica | B26: 0.8 | C26: Mes | D26: 1 | E26: 1200 | F26: 960
A27: Agua | B27: 0.7 | C27: Mes | D27: 1 | E27: 500 | F27: 350
A28: Gas LP | B28: 1 | C28: Mes | D28: 1 | E28: 1000 | F28: 1000
A29: Mantenimiento | B29: 0.7 | C29: Mes | D29: 1 | E29: 350 | F29: 350
A30: Depreciacion en eq. De producción | B30: 1 | C30: Mes | D30: 1 | E30: 1500 | F30: 1500
A31: Subtotal | F31: =SUM(F25:F30) -> 8960
A38: MEMORIA DE CALCULO MANO DE OBRA PARA LA INVERSION FIJA
A39: CONCEPTO | B39: MEDIDA | C39: CANT | D39: C.U. | E39: TOTAL
A40: Servicios profesionales de empresa constructora para adecuación del local (proyecto arquitectónico, obra civil, instalaciones eléctricas, plomería y acabados) | B40: Proyecto | C40: 1 | D40: $ 1,500,000.00 | E40: $ 1,500,000.00
A41: Supervisión y dirección de obra (incluida en contrato) | B41: Proyecto | C41: 1 | D41: Incluido
A42: Subtotal | E42: $ 1,500,000.00
A43: El monto corresponde al contrato global con la empresa de arquitectura encargada del diseño y construcción de la nueva sucursal. Incluye toda la mano de obra directa e indirecta del proyecto.
A51: MEMORIA DE CALCULO DE MOD
A52: Pago de salarios a personal de producción
B53: Sueldo semanal | C53: Sueldo neto semanal | D53: Sueldo neto mensual | E53: Sueldo neto bimestral
A54: Mesero | B54: 2100 | C54: 1691.61 | D54: 6766.43 | E54: 13532.87
A55: Verduras | B55: 1960 | C55: 1587.08 | D55: 6348.32 | E55: 12696.63
A56: Ensaladas | B56: 1960 | C56: 1587.08 | D56: 6348.32 | E56: 12696.63
A57: Guarniciones | B57: 1960 | C57: 1587.08 | D57: 6348.32 | E57: 12696.63
A58: Salsas y jarabes | B58: 1960 | C58: 1587.08 | D58: 6348.32 | E58: 12696.63
...

Sheet M. DE CALCULO DE GASTOS FIJO
A1: ESTRUCTURA DE INGRESOS Y EGRESOS
A3: MEMORIAS DE CALCULO GASTOS FIJOS
A5: PROYECTO: | B5: Taqueria Takirin "la chimenea"
A6: SOCIEDAD
A7: BENEFICIARIOS: | B7: Roberto Hernandez Lira
A8: MEMORIA DE CALCULO GASTOS DE ADMINISTRACIÓN | F8: MESES
B9: MEDIDA | C9: CANT | D9: C.U. | E9: TOTAL | F9: 1 | G9: 2 | H9: 3 | I9: 4 | J9: 5 | K9: 6 | L9: 7 | M9: 8 | N9: 9 | O9: 10 | P9: 11 | Q9: 12
A10: Renta del local | B10: Mes | C10: 2 | D10: 8000 | E10: =C10*D10 -> 16000 | F10: =$E$10 -> 16000 | G10: =$E$10 -> 16000 | H10: =$E$10 -> 16000 | I10: =$E$10 -> 16000 | J10: =$E$10 -> 16000 | K10: =$E$10 -> 16000 | L10: =$E$10 -> 16000 | M10: =$E$10 -> 16000 | ... Q10: =$E$10 -> 16000
A11: Internet / teléfono | B11: Mes | C11: 1 | D11: 600 | E11: 600 | F11: 600 | G11: 600 | H11: 600 | I11: 600 | J11: 600 | K11: 600 | L11: 600 | M11: 600 | N11: 600 | O11: 600 | P11: 600 | Q11: 600
A12: Permisos y licencias | B12: Mes | C12: 1 | D12: 400 | E12: 400 | F12: 400 | G12: 400 | H12: 400 | I12: 400 | J12: 400 | K12: 400 | L12: 400 | M12: 400 | N12: 400 | O12: 400 | P12: 400 | Q12: 400
A13: Mantenimiento | B13: Mes | C13: 1 | D13: 500 | E13: 500 | F13: 500 | G13: 500 | H13: 500 | I13: 500 | J13: 500 | K13: 500 | L13: 500 | M13: 500 | N13: 500 | O13: 500 | P13: 500 | Q13: 500
A14: Depreciaciones | B14: Mes | C14: 1 | D14: 1500 | E14: 1500 | F14: 1500 | G14: 1500 | H14: 1500 | I14: 1500 | J14: 1500 | K14: 1500 | L14: 1500 | M14: 1500 | N14: 1500 | O14: 1500 | P14: 1500 | Q14: 1500
A15: Subtotal | E15: =SUM(E10:E14) -> 19000 | F15: =SUM(F10:F14) -> 19000 | G15: =SUM(G10:G14) -> 19000 | H15: =SUM(H10:H14) -> 19000 | I15: =SUM(I10:I14) -> 19000 | J15: =SUM(J10:J14) -> 19000 | K15: =SUM(K10:K14) -> 19000 | L15: =SUM(L10:L14) -> 19000 | ... Q15: =SUM(Q10:Q14) -> 19000 | R15: =SUM(F15:Q15) -> 228000
A18: MEMORIA DE CALCULO GASTOS DE VENTA | F18: MESES
F19: 1 | G19: 2 | H19: 3 | I19: 4 | J19: 5 | K19: 6 | L19: 7 | M19: 8 | N19: 9 | O19: 10 | P19: 11 | Q19: 12
A20: Energía eléctrica (Pago bimestral) | B20: Mes | C20: 1 | D20: 700 | E20: 700 | F20: 700 | G20: 700 | H20: 700 | I20: 700 | J20: 700 | K20: 700 | L20: 700 | M20: 700 | N20: 700 | O20: 700 | P20: 700 | Q20: 700
A21: Agua | B21: Mes | C21: 1 | D21: 400 | E21: 400 | F21: 400 | G21: 400 | H21: 400 | I21: 400 | J21: 400 | K21: 400 | L21: 400 | M21: 400 | N21: 400 | O21: 400 | P21: 400 | Q21: 400
A22: Gas estacionario | B22: Mes | C22: 1 | D22: 1200 | E22: 1200 | F22: 1200 | G22: 1200 | H22: 1200 | I22: 1200 | J22: 1200 | K22: 1200 | L22: 1200 | M22: 1200 | N22: 1200 | O22: 1200 | P22: 1200 | Q22: 1200
A23: Limpieza / fumigación | B23: Mes | C23: 1 | D23: 300 | E23: 300 | F23: 300 | G23: 300 | H23: 300 | I23: 300 | J23: 300 | K23: 300 | L23: 300 | M23: 300 | N23: 300 | O23: 300 | P23: 300 | Q23: 300
A24: Nómina operativa | B24: Mes | C24: 16 | D24: 8000 | E24: =D24*C24 -> 128000 | F24: =$E$24 -> 128000 | G24: =$E$24 -> 128000 | H24: =$E$24 -> 128000 | I24: =$E$24 -> 128000 | J24: =$E$24 -> 128000 | K24: =$E$24 -> 128000 | L24: =$E$24 -> 128000 | M24: =$E$24 -> 128000 | ... Q24: =$E$24 -> 128000
A25: Subtotal | E25: =SUM(E20:E23) -> 2600 | F25: =SUM(F20:F23) -> 2600 | G25: =SUM(G20:G23) -> 2600 | H25: =SUM(H20:H23) -> 2600 | I25: =SUM(I20:I23) -> 2600 | J25: =SUM(J20:J23) -> 2600 | K25: =SUM(K20:K23) -> 2600 | L25: =SUM(L20:L23) -> 2600 | ... Q25: =SUM(Q20:Q23) -> 2600 | R25: =SUM(F25:Q25) -> 31200
A28: MEMORIA DE CALCULO GASTOS SOCIALES | F28: MESES
D29: C.U. | E29: TOTAL | F29: 1 | G29: 2 | H29: 3 | I29: 4 | J29: 5 | K29: 6 | L29: 7 | M29: 8 | N29: 9 | O29: 10 | P29: 11 | Q29: 12
A30: Nómina Operativa
A31: Mesero | C31: 3 | D31: =1691.61*4 -> 6766.44 | E31: =D31*C31 -> 20299.32 | F31: =$C$31*$D$31 -> 20299.32 | G31: =$C$31*$D$31 -> 20299.32 | H31: =$C$31*$D$31 -> 20299.32 | I31: =$C$31*$D$31 -> 20299.32 | J31: =$C$31*$D$31 -> 20299.32 | K31: =$C$31*$D$31 -> 20299.32 | L31: =$C$31*$D$31 -> 20299.32 | M31: =$C$31*$D$31 -> 20299.32 | ... Q31: =$C$31*$D$31 -> 20299.32
A32: Verduras, ensaladas y guarniciones | C32: 1 | D32: =1587.08*4 -> 6348.32 | E32: =$C$32*$D$32 -> 6348.32 | F32: =$C$32*$D$32 -> 6348.32 | G32: =$C$32*$D$32 -> 6348.32 | H32: =$C$32*$D$32 -> 6348.32 | I32: =$C$32*$D$32 -> 6348.32 | J32: =$C$32*$D$32 -> 6348.32 | K32: =$C$32*$D$32 -> 6348.32 | L32: =$C$32*$D$32 -> 6348.32 | ... Q32: =$C$32*$D$32 -> 6348.32
A33: Salsas y Járabes | C33: 1 | D33: =1587.08*4 -> 6348.32 | E33: =$C$33*$D$33 -> 6348.32 | F33: =$C$33*$D$33 -> 6348.32 | G33: =$C$33*$D$33 -> 6348.32 | H33: =$C$33*$D$33 -> 6348.32 | I33: =$C$33*$D$33 -> 6348.32 | J33: =$C$33*$D$33 -> 6348.32 | K33: =$C$33*$D$33 -> 6348.32 | L33: =$C$33*$D$33 -> 6348.32 | ... Q33: =$C$33*$D$33 -> 6348.32
A34: Coordinador de parrilla | C34: 1 | D34: =2776.69*4 -> 11106.76 | E34: =$C$34*$D$34 -> 11106.76 | F34: =$C$34*$D$34 -> 11106.76 | G34: =$C$34*$D$34 -> 11106.76 | H34: =$C$34*$D$34 -> 11106.76 | I34: =$C$34*$D$34 -> 11106.76 | J34: =$C$34*$D$34 -> 11106.76 | K34: =$C$34*$D$34 -> 11106.76 | L34: =$C$34*$D$34 -> 11106.76 | ... Q34: =$C$34*$D$34 -> 11106.76
A35: Parrillero plancha | C35: 1 | D35: =2223.75*4 -> 8895 | E35: =$C$35*$D$35 -> 8895 | F35: =$C$35*$D$35 -> 8895 | G35: =$C$35*$D$35 -> 8895 | H35: =$C$35*$D$35 -> 8895 | I35: =$C$35*$D$35 -> 8895 | J35: =$C$35*$D$35 -> 8895 | K35: =$C$35*$D$35 -> 8895 | L35: =$C$35*$D$35 -> 8895 | ... Q35: =$C$35*$D$35 -> 8895
A36: Parrillero vapor | C36: 1 | D36: =1965.59*4 -> 7862.36 | E36: =$C$36*$D$36 -> 7862.36 | F36: =$C$36*$D$36 -> 7862.36 | G36: =$C$36*$D$36 -> 7862.36 | H36: =$C$36*$D$36 -> 7862.36 | I36: =$C$36*$D$36 -> 7862.36 | J36: =$C$36*$D$36 -> 7862.36 | K36: =$C$36*$D$36 -> 7862.36 | L36: =$C$36*$D$36 -> 7862.36 | ... Q36: =$C$36*$D$36 -> 7862.36
A37: Pastorero | C37: 1 | D37: =2223.75*4 -> 8895 | E37: =$C$37*$D$37 -> 8895 | F37: =$C$37*$D$37 -> 8895 | G37: =$C$37*$D$37 -> 8895 | H37: =$C$37*$D$37 -> 8895 | I37: =$C$37*$D$37 -> 8895 | J37: =$C$37*$D$37 -> 8895 | K37: =$C$37*$D$37 -> 8895 | L37: =$C$37*$D$37 -> 8895 | ... Q37: =$C$37*$D$37 -> 8895
A38: Lavatrastes | C38: 1 | D38: =1587.08*4 -> 6348.32 | E38: =$C$38*$D$38 -> 6348.32 | F38: =$C$38*$D$38 -> 6348.32 | G38: =$C$38*$D$38 -> 6348.32 | H38: =$C$38*$D$38 -> 6348.32 | I38: =$C$38*$D$38 -> 6348.32 | J38: =$C$38*$D$38 -> 6348.32 | K38: =$C$38*$D$38 -> 6348.32 | L38: =$C$38*$D$38 -> 6348.32 | ... Q38: =$C$38*$D$38 -> 6348.32
A39: Nómina Administrativa
A40: Gerente general | C40: 1 | D40: =4315.99*4 -> 17263.96 | E40: =$C$40*$D$40 -> 17263.96 | F40: =$C$40*$D$40 -> 17263.96 | G40: =$C$40*$D$40 -> 17263.96 | H40: =$C$40*$D$40 -> 17263.96 | I40: =$C$40*$D$40 -> 17263.96 | J40: =$C$40*$D$40 -> 17263.96 | K40: =$C$40*$D$40 -> 17263.96 | L40: =$C$40*$D$40 -> 17263.96 | ... Q40: =$C$40*$D$40 -> 17263.96
A41: Asesor | C41: 1 | D41: =4301.08*4 -> 17204.32 | E41: =$C$41*$D$41 -> 17204.32 | F41: =$C$41*$D$41 -> 17204.32 | G41: =$C$41*$D$41 -> 17204.32 | H41: =$C$41*$D$41 -> 17204.32 | I41: =$C$41*$D$41 -> 17204.32 | J41: =$C$41*$D$41 -> 17204.32 | K41: =$C$41*$D$41 -> 17204.32 | L41: =$C$41*$D$41 -> 17204.32 | ... Q41: =$C$41*$D$41 -> 17204.32
A42: Cajero | C42: 1 | D42: =2094.39*4 -> 8377.56 | E42: =$C$42*$D$42 -> 8377.56 | F42: =$C$42*$D$42 -> 8377.56 | G42: =$C$42*$D$42 -> 8377.56 | H42: =$C$42*$D$42 -> 8377.56 | I42: =$C$42*$D$42 -> 8377.56 | J42: =$C$42*$D$42 -> 8377.56 | K42: =$C$42*$D$42 -> 8377.56 | L42: =$C$42*$D$42 -> 8377.56 | ... Q42: =$C$42*$D$42 -> 8377.56
A43: Contador | C43: 1 | D43: =3648.64*4 -> 14594.56 | E43: =$C$43*$D$43 -> 14594.56 | F43: =$C$43*$D$43 -> 14594.56 | G43: =$C$43*$D$43 -> 14594.56 | H43: =$C$43*$D$43 -> 14594.56 | I43: =$C$43*$D$43 -> 14594.56 | J43: =$C$43*$D$43 -> 14594.56 | K43: =$C$43*$D$43 -> 14594.56 | L43: =$C$43*$D$43 -> 14594.56 | ... Q43: =$C$43*$D$43 -> 14594.56
A44: Compras | C44: 1 | D44: =3974.86*4 -> 15899.44 | E44: =$C$44*$D$44 -> 15899.44 | F44: =$C$44*$D$44 -> 15899.44 | G44: =$C$44*$D$44 -> 15899.44 | H44: =$C$44*$D$44 -> 15899.44 | I44: =$C$44*$D$44 -> 15899.44 | J44: =$C$44*$D$44 -> 15899.44 | K44: =$C$44*$D$44 -> 15899.44 | L44: =$C$44*$D$44 -> 15899.44 | ... Q44: =$C$44*$D$44 -> 15899.44
A45: Supervisor de envios y calidad | C45: 1 | D45: =2996.21*4 -> 11984.84 | E45: =$C$45*$D$45 -> 11984.84 | F45: =$C$45*$D$45 -> 11984.84 | G45: =$C$45*$D$45 -> 11984.84 | H45: =$C$45*$D$45 -> 11984.84 | I45: =$C$45*$D$45 -> 11984.84 | J45: =$C$45*$D$45 -> 11984.84 | K45: =$C$45*$D$45 -> 11984.84 | L45: =$C$45*$D$45 -> 11984.84 | ... Q45: =$C$45*$D$45 -> 11984.84
A47: Seguro social (IMSS) | B47: Mes | C47: 16 | D47: 192.25 | E47: =$C$47*$D$47 -> 3076 | F47: =$C$47*$D$47 -> 3076 | G47: =$C$47*$D$47 -> 3076 | H47: =$C$47*$D$47 -> 3076 | I47: =$C$47*$D$47 -> 3076 | J47: =$C$47*$D$47 -> 3076 | K47: =$C$47*$D$47 -> 3076 | L47: =$C$47*$D$47 -> 3076 | ... Q47: =$C$47*$D$47 -> 3076
...

Sheet COSTOS 
A2: COSTOS DE PRODUCCION AÑO 1
A3: VARIABLES | B3: 1 | C3: 2 | D3: 3 | E3: 4 | F3: 5 | G3: 6 | H3: 7 | I3: 8 | J3: 9 | K3: 10 | L3: 11 | M3: 12 | N3: TOTAL | Q3: VARIABLES | R3: AÑO 1 | S3: AÑO 2 | T3: AÑO 3 | U3: AÑO 4 | V3: AÑO 5
A4: TOTAL VARIABLES | B4: =SUM(B5:B15) -> 193560 | C4: =SUM(C5:C15) -> 197431.2 | D4: =SUM(D5:D15) -> 193482.58 | E4: =SUM(E5:E15) -> 199287.05 | F4: =SUM(F5:F15) -> 203272.79 | G4: =SUM(G5:G15) -> 197174.61 | H4: =SUM(H5:H15) -> 195202.86 | I4: =SUM(I5:I15) -> 199106.92 | ... N4: =SUM(N5:N15) -> 2364831.1 | Q4: TOTAL VARIABLES | R4: =SUM(R5:R16) -> 2364831.1 | S4: =SUM(S5:S16) -> 2455457.9 | T4: =SUM(T5:T16) -> 2549557.7 | U4: =SUM(U5:U16) -> 2647263.7 | V4: =SUM(V5:V16) -> 2748714
A5: ='M. DE CALCULO DE COSTOS VAR'!A12 -> Carne de cerdo adobada al pastor | B5: ='M. DE CALCULO DE COSTOS VAR'!E12+'M. DE CALCULO DE COSTOS VAR'!Q12 -> 114000 | C5: =B5*1.02 -> 116280 | D5: =C5*0.98 -> 113954.4 | E5: =D5*1.03 -> 117373.03 | F5: =E5*1.02 -> 119720.49 | G5: =F5*0.97 -> 116128.88 | H5: =G5*0.99 -> 114967.59 | I5: =H5*1.02 -> 117266.94 | J5: =I5*0.98 -> 114921.6 | K5: =J5*0.99 -> 113772.39 | L5: =K5*1.02 -> 116047.83 | M5: =1.02*L5 -> 118368.79 | N5: =SUM(B5:M5) -> 1392801.9 | Q5: =A5 -> Carne de cerdo adobada al pastor | R5: =N5 -> 1392801.9 | S5: =N58 -> 1446177.9 | T5: =N111 -> 1501599.4 | U5: =N164 -> 1559144.8 | V5: =N217 -> 1618895.4
A6: ='M. DE CALCULO DE COSTOS VAR'!A13 -> Tortilla de maíz | B6: ='M. DE CALCULO DE COSTOS VAR'!E13+'M. DE CALCULO DE COSTOS VAR'!Q14 -> 4560 | C6: =B6*1.02 -> 4651.2 | D6: =C6*0.98 -> 4558.176 | E6: =D6*1.03 -> 4694.9213 | F6: =E6*1.02 -> 4788.8197 | G6: =F6*0.97 -> 4645.1551 | H6: =G6*0.99 -> 4598.7036 | I6: =H6*1.02 -> 4690.6776 | J6: =I6*0.98 -> 4596.8641 | K6: =J6*0.99 -> 4550.8954 | L6: =K6*1.02 -> 4641.9133 | M6: =1.02*L6 -> 4734.7516 | N6: =SUM(B6:M6) -> 55712.078 | Q6: =A6 -> Tortilla de maíz | R6: =N6 -> 55712.078 | S6: =N59 -> 57847.116 | T6: =N112 -> 60063.975 | U6: =N165 -> 62365.79 | V6: =N218 -> 64755.817
A7: ='M. DE CALCULO DE COSTOS VAR'!A14 -> Piña | B7: ='M. DE CALCULO DE COSTOS VAR'!E14 -> 2400 | C7: =B7*1.02 -> 2448 | D7: =C7*0.98 -> 2399.04 | E7: =D7*1.03 -> 2471.0112 | F7: =E7*1.02 -> 2520.4314 | G7: =F7*0.97 -> 2444.8185 | H7: =G7*0.99 -> 2420.3703 | I7: =H7*1.02 -> 2468.7777 | J7: =I7*0.98 -> 2419.4021 | K7: =J7*0.99 -> 2395.2081 | L7: =K7*1.02 -> 2443.1123 | M7: =1.02*L7 -> 2491.9745 | N7: =SUM(B7:M7) -> 29322.146 | Q7: =A7 -> Piña | R7: =N7 -> 29322.146 | S7: =N60 -> 30445.851 | T7: =N113 -> 31612.619 | U7: =N166 -> 32824.1 | V7: =N219 -> 34082.009
A8: ='M. DE CALCULO DE COSTOS VAR'!A15 -> Cebolla | B8: ='M. DE CALCULO DE COSTOS VAR'!E15 -> 1200 | C8: =B8*1.02 -> 1224 | D8: =C8*0.98 -> 1199.52 | E8: =D8*1.03 -> 1235.5056 | F8: =E8*1.02 -> 1260.2157 | G8: =F8*0.97 -> 1222.4092 | H8: =G8*0.99 -> 1210.1851 | I8: =H8*1.02 -> 1234.3889 | J8: =I8*0.98 -> 1209.7011 | K8: =J8*0.99 -> 1197.6041 | L8: =K8*1.02 -> 1221.5561 | M8: =1.02*L8 -> 1245.9873 | N8: =SUM(B8:M8) -> 14661.073 | Q8: =A8 -> Cebolla | R8: =N8 -> 14661.073 | S8: =N61 -> 15222.925 | T8: =N114 -> 15806.309 | U8: =N167 -> 16412.05 | V8: =N220 -> 17041.005
A9: ='M. DE CALCULO DE COSTOS VAR'!A16 -> Cilantro | B9: ='M. DE CALCULO DE COSTOS VAR'!E16 -> 1200 | C9: =B9*1.02 -> 1224 | D9: =C9*0.98 -> 1199.52 | E9: =D9*1.03 -> 1235.5056 | F9: =E9*1.02 -> 1260.2157 | G9: =F9*0.97 -> 1222.4092 | H9: =G9*0.99 -> 1210.1851 | I9: =H9*1.02 -> 1234.3889 | J9: =I9*0.98 -> 1209.7011 | K9: =J9*0.99 -> 1197.6041 | L9: =K9*1.02 -> 1221.5561 | M9: =1.02*L9 -> 1245.9873 | N9: =SUM(B9:M9) -> 14661.073 | Q9: =A9 -> Cilantro | R9: =N9 -> 14661.073 | S9: =N62 -> 15222.925 | T9: =N115 -> 15806.309 | U9: =N168 -> 16412.05 | V9: =N221 -> 17041.005
A10: {='M. DE CALCULO DE COSTOS VAR'!G12:G13} -> Carne de cerdo marinada estilo oriental | B10: ='M. DE CALCULO DE COSTOS VAR'!K12 -> 45000 | C10: =B10*1.02 -> 45900 | D10: =C10*0.98 -> 44982 | E10: =D10*1.03 -> 46331.46 | F10: =E10*1.02 -> 47258.089 | G10: =F10*0.97 -> 45840.347 | H10: =G10*0.99 -> 45381.943 | I10: =H10*1.02 -> 46289.582 | J10: =I10*0.98 -> 45363.79 | K10: =J10*0.99 -> 44910.152 | L10: =K10*1.02 -> 45808.355 | M10: =1.02*L10 -> 46724.523 | N10: =SUM(B10:M10) -> 549790.24 | Q10: =A10 -> Carne de cerdo marinada estilo oriental | R10: =N10 -> 549790.24 | S10: =N63 -> 570859.7 | T10: =N116 -> 592736.6 | U10: =N169 -> 615451.88 | V10: =N222 -> 639037.67
A11: Pan árabe (Pita) | B11: ='M. DE CALCULO DE COSTOS VAR'!K13 -> 3600 | C11: =B11*1.02 -> 3672 | D11: =C11*0.98 -> 3598.56 | E11: =D11*1.03 -> 3706.5168 | F11: =E11*1.02 -> 3780.6471 | G11: =F11*0.97 -> 3667.2277 | H11: =G11*0.99 -> 3630.5554 | I11: =H11*1.02 -> 3703.1666 | J11: =I11*0.98 -> 3629.1032 | K11: =J11*0.99 -> 3592.8122 | L11: =K11*1.02 -> 3664.6684 | M11: =1.02*L11 -> 3737.9618 | N11: =SUM(B11:M11) -> 43983.219 | Q11: =A11 -> Pan árabe (Pita) | R11: =N11 -> 43983.219 | S11: =N64 -> 45668.776 | T11: =N117 -> 47418.928 | U11: =N170 -> 49236.15 | V11: =N223 -> 51123.014
A12: ='M. DE CALCULO DE COSTOS VAR'!M13 -> Tocino | B12: ='M. DE CALCULO DE COSTOS VAR'!Q13 -> 12600 | C12: =B12*1.02 -> 12852 | D12: =C12*0.98 -> 12594.96 | E12: =D12*1.03 -> 12972.809 | F12: =E12*1.02 -> 13232.265 | G12: =F12*0.97 -> 12835.297 | H12: =G12*0.99 -> 12706.944 | I12: =H12*1.02 -> 12961.083 | J12: =I12*0.98 -> 12701.861 | K12: =J12*0.99 -> 12574.843 | L12: =K12*1.02 -> 12826.34 | M12: =1.02*L12 -> 13082.866 | N12: =SUM(B12:M12) -> 153941.27 | Q12: =A12 -> Tocino | R12: =N12 -> 153941.27 | S12: =N65 -> 159840.72 | T12: =N118 -> 165966.25 | U12: =N171 -> 172326.53 | V12: =N224 -> 178930.55
A13: {='M. DE CALCULO DE COSTOS VAR'!M15:M17} -> Chile poblano | B13: ='M. DE CALCULO DE COSTOS VAR'!Q15 -> 3600 | C13: =B13*1.02 -> 3672 | D13: =C13*0.98 -> 3598.56 | E13: =D13*1.03 -> 3706.5168 | F13: =E13*1.02 -> 3780.6471 | G13: =F13*0.97 -> 3667.2277 | H13: =G13*0.99 -> 3630.5554 | I13: =H13*1.02 -> 3703.1666 | J13: =I13*0.98 -> 3629.1032 | K13: =J13*0.99 -> 3592.8122 | L13: =K13*1.02 -> 3664.6684 | M13: =1.02*L13 -> 3737.9618 | N13: =SUM(B13:M13) -> 43983.219 | Q13: =A13 -> Chile poblano | R13: =N13 -> 43983.219 | S13: =N66 -> 45668.776 | T13: =N119 -> 47418.928 | U13: =N172 -> 49236.15 | V13: =N225 -> 51123.014
A14: Cebolla | B14: ='M. DE CALCULO DE COSTOS VAR'!Q16 -> 3000 | C14: =B14*1.02 -> 3060 | D14: =C14*0.98 -> 2998.8 | E14: =D14*1.03 -> 3088.764 | F14: =E14*1.02 -> 3150.5393 | G14: =F14*0.97 -> 3056.0231 | H14: =G14*0.99 -> 3025.4629 | I14: =H14*1.02 -> 3085.9721 | J14: =I14*0.98 -> 3024.2527 | K14: =J14*0.99 -> 2994.0102 | L14: =K14*1.02 -> 3053.8904 | M14: =1.02*L14 -> 3114.9682 | N14: =SUM(B14:M14) -> 36652.683 | Q14: =A14 -> Cebolla | R14: =N14 -> 36652.683 | S14: =N67 -> 38057.313 | T14: =N120 -> 39515.773 | U14: =N173 -> 41030.125 | V14: =N226 -> 42602.511
A15: Jitomate | B15: ='M. DE CALCULO DE COSTOS VAR'!Q17 -> 2400 | C15: =B15*1.02 -> 2448 | D15: =C15*0.98 -> 2399.04 | E15: =D15*1.03 -> 2471.0112 | F15: =E15*1.02 -> 2520.4314 | G15: =F15*0.97 -> 2444.8185 | H15: =G15*0.99 -> 2420.3703 | I15: =H15*1.02 -> 2468.7777 | J15: =I15*0.98 -> 2419.4021 | K15: =J15*0.99 -> 2395.2081 | L15: =K15*1.02 -> 2443.1123 | M15: =1.02*L15 -> 2491.9745 | N15: =SUM(B15:M15) -> 29322.146 | Q15: =A15 -> Jitomate | R15: =N15 -> 29322.146 | S15: =N68 -> 30445.851 | T15: =N121 -> 31612.619 | U15: =N174 -> 32824.1 | V15: =N227 -> 34082.009
A16: TOTAL FIJOS | B16: =SUM(B17:B41,B46:B52) -> 207422.46 | C16: =SUM(C17:C41,C46:C52) -> 207422.46 | D16: =SUM(D17:D41,D46:D52) -> 207422.46 | E16: =SUM(E17:E41,E46:E52) -> 207422.46 | F16: =SUM(F17:F41,F46:F52) -> 207422.46 | G16: =SUM(G17:G41,G46:G52) -> 207422.46 | H16: =SUM(H17:H41,H46:H52) -> 207422.46 | I16: =SUM(I17:I41,I46:I52) -> 207422.46 | ... N16: =SUM(N17:N41,N46:N52) -> 2489069.5
A17: ='M. DE CALCULO DE GASTOS FIJO'!A10 -> Renta del local | B17: {='M. DE CALCULO DE GASTOS FIJO'!E10:E14} -> 16000 | C17: =B17 -> 16000 | D17: =C17 -> 16000 | E17: =D17 -> 16000 | F17: =E17 -> 16000 | G17: =F17 -> 16000 | H17: =G17 -> 16000 | I17: =H17 -> 16000 | J17: =I17 -> 16000 | ... M17: =L17 -> 16000 | N17: =SUM(B17:M17) -> 192000 | Q17: TOTAL FIJOS | R17: =N16 -> 2489069.5 | S17: =N69 -> 2489069.5 | T17: =N122 -> 2489069.5 | U17: =N175 -> 2489069.5 | V17: =N228 -> 2489069.5
A18: ='M. DE CALCULO DE GASTOS FIJO'!A11 -> Internet / teléfono | B18: 600 | C18: =B18 -> 600 | D18: =C18 -> 600 | E18: =D18 -> 600 | F18: =E18 -> 600 | G18: =F18 -> 600 | H18: =G18 -> 600 | I18: =H18 -> 600 | J18: =I18 -> 600 | ... M18: =L18 -> 600 | N18: =SUM(B18:M18) -> 7200 | Q18: =A17 -> Renta del local | R18: =M17 -> 16000 | S18: =R18 -> 16000 | T18: =S18 -> 16000 | U18: =T18 -> 16000 | V18: =U18 -> 16000
A19: ='M. DE CALCULO DE GASTOS FIJO'!A12 -> Permisos y licencias | B19: 400 | C19: =B19 -> 400 | D19: =C19 -> 400 | E19: =D19 -> 400 | F19: =E19 -> 400 | G19: =F19 -> 400 | H19: =G19 -> 400 | I19: =H19 -> 400 | J19: =I19 -> 400 | ... M19: =L19 -> 400 | N19: =SUM(B19:M19) -> 4800 | Q19: =A18 -> Internet / teléfono | R19: =M18 -> 600 | S19: =R19 -> 600 | T19: =S19 -> 600 | U19: =T19 -> 600 | V19: =U19 -> 600
A20: ='M. DE CALCULO DE GASTOS FIJO'!A13 -> Mantenimiento | B20: 500 | C20: =B20 -> 500 | D20: =C20 -> 500 | E20: =D20 -> 500 | F20: =E20 -> 500 | G20: =F20 -> 500 | H20: =G20 -> 500 | I20: =H20 -> 500 | J20: =I20 -> 500 | ... M20: =L20 -> 500 | N20: =SUM(B20:M20) -> 6000 | Q20: =A19 -> Permisos y licencias | R20: =M19 -> 400 | S20: =R20 -> 400 | T20: =S20 -> 400 | U20: =T20 -> 400 | V20: =U20 -> 400
A21: ='M. DE CALCULO DE GASTOS FIJO'!A14 -> Depreciaciones | B21: 1500 | C21: =B21 -> 1500 | D21: =C21 -> 1500 | E21: =D21 -> 1500 | F21: =E21 -> 1500 | G21: =F21 -> 1500 | H21: =G21 -> 1500 | I21: =H21 -> 1500 | J21: =I21 -> 1500 | ... M21: =L21 -> 1500 | N21: =SUM(B21:M21) -> 18000 | Q21: =A20 -> Mantenimiento | R21: =M20 -> 500 | S21: =R21 -> 500 | T21: =S21 -> 500 | U21: =T21 -> 500 | V21: =U21 -> 500
A22: {='M. DE CALCULO DE GASTOS FIJO'!A20:A23} -> Energía eléctrica (Pago bimestral) | B22: {='M. DE CALCULO DE GASTOS FIJO'!E20:E23} -> 700 | C22: =B22 -> 700 | D22: =C22 -> 700 | E22: =D22 -> 700 | F22: =E22 -> 700 | G22: =F22 -> 700 | H22: =G22 -> 700 | I22: =H22 -> 700 | J22: =I22 -> 700 | ... M22: =L22 -> 700 | N22: =SUM(B22:M22) -> 8400 | Q22: =A21 -> Depreciaciones | R22: =M21 -> 1500 | S22: =R22 -> 1500 | T22: =S22 -> 1500 | U22: =T22 -> 1500 | V22: =U22 -> 1500 | Y22: v
A23: Agua | B23: 400 | C23: =B23 -> 400 | D23: =C23 -> 400 | E23: =D23 -> 400 | F23: =E23 -> 400 | G23: =F23 -> 400 | H23: =G23 -> 400 | I23: =H23 -> 400 | J23: =I23 -> 400 | ... M23: =L23 -> 400 | N23: =SUM(B23:M23) -> 4800 | Q23: =A22 -> Energía eléctrica (Pago bimestral) | R23: =M22 -> 700 | S23: =R23 -> 700 | T23: =S23 -> 700 | U23: =T23 -> 700 | V23: =U23 -> 700
A24: Gas estacionario | B24: 1200 | C24: =B24 -> 1200 | D24: =C24 -> 1200 | E24: =D24 -> 1200 | F24: =E24 -> 1200 | G24: =F24 -> 1200 | H24: =G24 -> 1200 | I24: =H24 -> 1200 | J24: =I24 -> 1200 | ... M24: =L24 -> 1200 | N24: =SUM(B24:M24) -> 14400 | Q24: =A23 -> Agua | R24: =M23 -> 400 | S24: =R24 -> 400 | T24: =S24 -> 400 | U24: =T24 -> 400 | V24: =U24 -> 400
A25: Limpieza / fumigación | B25: 300 | C25: =B25 -> 300 | D25: =C25 -> 300 | E25: =D25 -> 300 | F25: =E25 -> 300 | G25: =F25 -> 300 | H25: =G25 -> 300 | I25: =H25 -> 300 | J25: =I25 -> 300 | ... M25: =L25 -> 300 | N25: =SUM(B25:M25) -> 3600 | Q25: =A24 -> Gas estacionario | R25: =M24 -> 1200 | S25: =R25 -> 1200 | T25: =S25 -> 1200 | U25: =T25 -> 1200 | V25: =U25 -> 1200
A26: {='M. DE CALCULO DE GASTOS FIJO'!A31:A38} -> Mesero | B26: {='M. DE CALCULO DE GASTOS FIJO'!E31:E38} -> 20299.32 | C26: =B26 -> 20299.32 | D26: =C26 -> 20299.32 | E26: =D26 -> 20299.32 | F26: =E26 -> 20299.32 | G26: =F26 -> 20299.32 | H26: =G26 -> 20299.32 | I26: =H26 -> 20299.32 | J26: =I26 -> 20299.32 | ... M26: =L26 -> 20299.32 | N26: =SUM(B26:M26) -> 243591.84 | Q26: =A25 -> Limpieza / fumigación | R26: =M25 -> 300 | S26: =R26 -> 300 | T26: =S26 -> 300 | U26: =T26 -> 300 | V26: =U26 -> 300
A27: Verduras, ensaladas y guarniciones | B27: 6348.32 | C27: =B27 -> 6348.32 | D27: =C27 -> 6348.32 | E27: =D27 -> 6348.32 | F27: =E27 -> 6348.32 | G27: =F27 -> 6348.32 | H27: =G27 -> 6348.32 | I27: =H27 -> 6348.32 | J27: =I27 -> 6348.32 | ... M27: =L27 -> 6348.32 | N27: =SUM(B27:M27) -> 76179.84 | Q27: =A26 -> Mesero | R27: =M26 -> 20299.32 | S27: =R27 -> 20299.32 | T27: =S27 -> 20299.32 | U27: =T27 -> 20299.32 | V27: =U27 -> 20299.32
A28: Salsas y Járabes | B28: 6348.32 | C28: =B28 -> 6348.32 | D28: =C28 -> 6348.32 | E28: =D28 -> 6348.32 | F28: =E28 -> 6348.32 | G28: =F28 -> 6348.32 | H28: =G28 -> 6348.32 | I28: =H28 -> 6348.32 | J28: =I28 -> 6348.32 | ... M28: =L28 -> 6348.32 | N28: =SUM(B28:M28) -> 76179.84 | Q28: =A27 -> Verduras, ensaladas y guarniciones | R28: =M27 -> 6348.32 | S28: =R28 -> 6348.32 | T28: =S28 -> 6348.32 | U28: =T28 -> 6348.32 | V28: =U28 -> 6348.32
A29: Coordinador de parrilla | B29: 11106.76 | C29: =B29 -> 11106.76 | D29: =C29 -> 11106.76 | E29: =D29 -> 11106.76 | F29: =E29 -> 11106.76 | G29: =F29 -> 11106.76 | H29: =G29 -> 11106.76 | I29: =H29 -> 11106.76 | J29: =I29 -> 11106.76 | ... M29: =L29 -> 11106.76 | N29: =SUM(B29:M29) -> 133281.12 | Q29: =A28 -> Salsas y Járabes | R29: =M28 -> 6348.32 | S29: =R29 -> 6348.32 | T29: =S29 -> 6348.32 | U29: =T29 -> 6348.32 | V29: =U29 -> 6348.32
A30: Parrillero plancha | B30: 8895 | C30: =B30 -> 8895 | D30: =C30 -> 8895 | E30: =D30 -> 8895 | F30: =E30 -> 8895 | G30: =F30 -> 8895 | H30: =G30 -> 8895 | I30: =H30 -> 8895 | J30: =I30 -> 8895 | ... M30: =L30 -> 8895 | N30: =SUM(B30:M30) -> 106740 | Q30: =A29 -> Coordinador de parrilla | R30: =M29 -> 11106.76 | S30: =R30 -> 11106.76 | T30: =S30 -> 11106.76 | U30: =T30 -> 11106.76 | V30: =U30 -> 11106.76
A31: Parrillero vapor | B31: 7862.36 | C31: =B31 -> 7862.36 | D31: =C31 -> 7862.36 | E31: =D31 -> 7862.36 | F31: =E31 -> 7862.36 | G31: =F31 -> 7862.36 | H31: =G31 -> 7862.36 | I31: =H31 -> 7862.36 | J31: =I31 -> 7862.36 | ... M31: =L31 -> 7862.36 | N31: =SUM(B31:M31) -> 94348.32 | Q31: =A30 -> Parrillero plancha | R31: =M30 -> 8895 | S31: =R31 -> 8895 | T31: =S31 -> 8895 | U31: =T31 -> 8895 | V31: =U31 -> 8895
A32: Pastorero | B32: 8895 | C32: =B32 -> 8895 | D32: =C32 -> 8895 | E32: =D32 -> 8895 | F32: =E32 -> 8895 | G32: =F32 -> 8895 | H32: =G32 -> 8895 | I32: =H32 -> 8895 | J32: =I32 -> 8895 | ... M32: =L32 -> 8895 | N32: =SUM(B32:M32) -> 106740 | Q32: =A31 -> Parrillero vapor | R32: =M31 -> 7862.36 | S32: =R32 -> 7862.36 | T32: =S32 -> 7862.36 | U32: =T32 -> 7862.36 | V32: =U32 -> 7862.36
A33: Lavatrastes | B33: 6348.32 | C33: =B33 -> 6348.32 | D33: =C33 -> 6348.32 | E33: =D33 -> 6348.32 | F33: =E33 -> 6348.32 | G33: =F33 -> 6348.32 | H33: =G33 -> 6348.32 | I33: =H33 -> 6348.32 | J33: =I33 -> 6348.32 | ... M33: =L33 -> 6348.32 | N33: =SUM(B33:M33) -> 76179.84 | Q33: =A32 -> Pastorero | R33: =M32 -> 8895 | S33: =R33 -> 8895 | T33: =S33 -> 8895 | U33: =T33 -> 8895 | V33: =U33 -> 8895
A34: {='M. DE CALCULO DE GASTOS FIJO'!A40:A45} -> Gerente general | B34: {='M. DE CALCULO DE GASTOS FIJO'!E40:E45} -> 17263.96 | C34: =B34 -> 17263.96 | D34: =C34 -> 17263.96 | E34: =D34 -> 17263.96 | F34: =E34 -> 17263.96 | G34: =F34 -> 17263.96 | H34: =G34 -> 17263.96 | I34: =H34 -> 17263.96 | J34: =I34 -> 17263.96 | ... M34: =L34 -> 17263.96 | N34: =SUM(B34:M34) -> 207167.52 | Q34: =A33 -> Lavatrastes | R34: =M33 -> 6348.32 | S34: =R34 -> 6348.32 | T34: =S34 -> 6348.32 | U34: =T34 -> 6348.32 | V34: =U34 -> 6348.32
A35: Asesor | B35: 17204.32 | C35: =B35 -> 17204.32 | D35: =C35 -> 17204.32 | E35: =D35 -> 17204.32 | F35: =E35 -> 17204.32 | G35: =F35 -> 17204.32 | H35: =G35 -> 17204.32 | I35: =H35 -> 17204.32 | J35: =I35 -> 17204.32 | ... M35: =L35 -> 17204.32 | N35: =SUM(B35:M35) -> 206451.84 | Q35: =A34 -> Gerente general | R35: =M34 -> 17263.96 | S35: =R35 -> 17263.96 | T35: =S35 -> 17263.96 | U35: =T35 -> 17263.96 | V35: =U35 -> 17263.96
A36: Cajero | B36: 8377.56 | C36: =B36 -> 8377.56 | D36: =C36 -> 8377.56 | E36: =D36 -> 8377.56 | F36: =E36 -> 8377.56 | G36: =F36 -> 8377.56 | H36: =G36 -> 8377.56 | I36: =H36 -> 8377.56 | J36: =I36 -> 8377.56 | ... M36: =L36 -> 8377.56 | N36: =SUM(B36:M36) -> 100530.72 | Q36: =A35 -> Asesor | R36: =M35 -> 17204.32 | S36: =R36 -> 17204.32 | T36: =S36 -> 17204.32 | U36: =T36 -> 17204.32 | V36: =U36 -> 17204.32
A37: Contador | B37: 14594.56 | C37: =B37 -> 14594.56 | D37: =C37 -> 14594.56 | E37: =D37 -> 14594.56 | F37: =E37 -> 14594.56 | G37: =F37 -> 14594.56 | H37: =G37 -> 14594.56 | I37: =H37 -> 14594.56 | J37: =I37 -> 14594.56 | ... M37: =L37 -> 14594.56 | N37: =SUM(B37:M37) -> 175134.72 | Q37: =A36 -> Cajero | R37: =M36 -> 8377.56 | S37: =R37 -> 8377.56 | T37: =S37 -> 8377.56 | U37: =T37 -> 8377.56 | V37: =U37 -> 8377.56
A38: Compras | B38: 15899.44 | C38: =B38 -> 15899.44 | D38: =C38 -> 15899.44 | E38: =D38 -> 15899.44 | F38: =E38 -> 15899.44 | G38: =F38 -> 15899.44 | H38: =G38 -> 15899.44 | I38: =H38 -> 15899.44 | J38: =I38 -> 15899.44 | ... M38: =L38 -> 15899.44 | N38: =SUM(B38:M38) -> 190793.28 | Q38: =A37 -> Contador | R38: =M37 -> 14594.56 | S38: =R38 -> 14594.56 | T38: =S38 -> 14594.56 | U38: =T38 -> 14594.56 | V38: =U38 -> 14594.56
A39: Supervisor de envios y calidad | B39: 11984.84 | C39: =B39 -> 11984.84 | D39: =C39 -> 11984.84 | E39: =D39 -> 11984.84 | F39: =E39 -> 11984.84 | G39: =F39 -> 11984.84 | H39: =G39 -> 11984.84 | I39: =H39 -> 11984.84 | J39: =I39 -> 11984.84 | ... M39: =L39 -> 11984.84 | N39: =SUM(B39:M39) -> 143818.08 | Q39: =A38 -> Compras | R39: =M38 -> 15899.44 | S39: =R39 -> 15899.44 | T39: =S39 -> 15899.44 | U39: =T39 -> 15899.44 | V39: =U39 -> 15899.44
A40: {='M. DE CALCULO DE GASTOS FIJO'!A47:A51} -> Seguro social (IMSS) | B40: {='M. DE CALCULO DE GASTOS FIJO'!E47:E51} -> 3076 | C40: =B40 -> 3076 | D40: =C40 -> 3076 | E40: =D40 -> 3076 | F40: =E40 -> 3076 | G40: =F40 -> 3076 | H40: =G40 -> 3076 | I40: =H40 -> 3076 | J40: =I40 -> 3076 | ... M40: =L40 -> 3076 | N40: =SUM(B40:M40) -> 36912 | Q40: =A39 -> Supervisor de envios y calidad | R40: =M39 -> 11984.84 | S40: =R40 -> 11984.84 | T40: =S40 -> 11984.84 | U40: =T40 -> 11984.84 | V40: =U40 -> 11984.84
A41: INFONAVIT | B41: 20318.376 | C41: =B41 -> 20318.376 | D41: =C41 -> 20318.376 | E41: =D41 -> 20318.376 | F41: =E41 -> 20318.376 | G41: =F41 -> 20318.376 | H41: =G41 -> 20318.376 | I41: =H41 -> 20318.376 | J41: =I41 -> 20318.376 | ... M41: =L41 -> 20318.376 | N41: =SUM(B41:M41) -> 243820.51 | Q41: =A40 -> Seguro social (IMSS) | R41: =M40 -> 3076 | S41: =R41 -> 3076 | T41: =S41 -> 3076 | U41: =T41 -> 3076 | V41: =U41 -> 3076
...

Sheet INGRESOS 
A2: MEMORIAS DE INGRESOS
A4: PROYECTO:
A5: SOCIEDAD
A6: BENEFICIARIOS:
A8: CONCEPTOS | B8: INGRESOS POR VENTA MENSUAL AÑO 1
A9: MES | B9: 1 | C9: 2 | D9: 3 | E9: 4 | F9: 5 | G9: 6 | H9: 7 | I9: 8 | J9: 9 | K9: 10 | L9: 11 | M9: 12 | N9: TOTAL
A10: Productos del local | N10: ANUAL
A11: Tacos al pastor | B11: =(16*(400*30)) -> 192000 | C11: =16*(400*30) -> 192000 | D11: =16*(400*30) -> 192000 | E11: =16*(412*30) -> 197760 | F11: =16*(412*30) -> 197760 | G11: =16*(412*30) -> 197760 | H11: =16*(425*30) -> 204000 | I11: =16*(425*30) -> 204000 | J11: =16*(425*30) -> 204000 | K11: =16*(438*30) -> 210240 | L11: =16*(438*30) -> 210240 | M11: =16*(438*30) -> 210240 | N11: =SUM(B11:M11) -> 2412000
A12: Taco arabe gigante | B12: =100*(130*30) -> 390000 | C12: =100*(130*30) -> 390000 | D12: =100*(130*30) -> 390000 | E12: =100*(134*30) -> 402000 | F12: =100*(134*30) -> 402000 | G12: =100*(134*30) -> 402000 | H12: =100*(138*30) -> 414000 | I12: =100*(138*30) -> 414000 | J12: =100*(138*30) -> 414000 | K12: =100*(143*30) -> 429000 | L12: =100*(143*30) -> 429000 | M12: =100*(143*30) -> 429000 | N12: =SUM(B12:M12) -> 4905000
A13: Matahambre | B13: =220*(50*30) -> 330000 | C13: =220*(50*30) -> 330000 | D13: =220*(50*30) -> 330000 | E13: =220*(52*30) -> 343200 | F13: =220*(52*30) -> 343200 | G13: =220*(52*30) -> 343200 | H13: =(220)*(54*30) -> 356400 | I13: =(220)*(54*30) -> 356400 | J13: =(220)*(54*30) -> 356400 | K13: =(220)*(56*30) -> 369600 | L13: =(220)*(56*30) -> 369600 | M13: =(220)*(56*30) -> 369600 | N13: =SUM(B13:M13) -> 4197600
A14: 1 litro de agua de horchata | B14: =(45)*(280*4) -> 50400 | C14: =(45)*(280*4) -> 50400 | D14: =(45)*(280*4) -> 50400 | E14: =(45)*(288*4) -> 51840 | F14: =(45)*(288*4) -> 51840 | G14: =(45)*(288*4) -> 51840 | H14: =(45)*(295*4) -> 53100 | I14: =(45)*(295*4) -> 53100 | J14: =(45)*(295*4) -> 53100 | K14: =(45)*(303*4) -> 54540 | L14: =(45)*(303*4) -> 54540 | M14: =(45)*(303*4) -> 54540 | N14: =SUM(B14:M14) -> 629640
A15: Una tazas de cafe americano | B15: =(20)*(5*30) -> 3000 | C15: =(20)*(5*30) -> 3000 | D15: =(20)*(5*30) -> 3000 | E15: =(20)*(5*30) -> 3000 | F15: =(20)*(5*30) -> 3000 | G15: =(20)*(5*30) -> 3000 | H15: =(20)*(5*30) -> 3000 | I15: =(20)*(5*30) -> 3000 | ... M15: =(20)*(5*30) -> 3000 | N15: =SUM(B15:M15) -> 36000
A16: Tortas hawaiana | B16: =(75)*(15*30) -> 33750 | C16: =(75)*(15*30) -> 33750 | D16: =(75)*(15*30) -> 33750 | E16: =(75)*(15*30) -> 33750 | F16: =(75)*(15*30) -> 33750 | G16: =(75)*(15*30) -> 33750 | H16: =(75)*(16*30) -> 36000 | I16: =(75)*(16*30) -> 36000 | J16: =(75)*(16*30) -> 36000 | K16: =(75)*(16*30) -> 36000 | L16: =(75)*(16*30) -> 36000 | M16: =(75)*(16*30) -> 36000 | N16: =SUM(B16:M16) -> 418500
A17: Hamburguesa Hawaiana | B17: =(75)*(10*30) -> 22500 | C17: =(75)*(10*30) -> 22500 | D17: =(75)*(10*30) -> 22500 | E17: =(75)*(10*30) -> 22500 | F17: =(75)*(10*30) -> 22500 | G17: =(75)*(10*30) -> 22500 | H17: =(75)*(10*30) -> 22500 | I17: =(75)*(10*30) -> 22500 | J17: =(75)*(10*30) -> 22500 | K17: =(75)*(11*30) -> 24750 | L17: =(75)*(11*30) -> 24750 | M17: =(75)*(11*30) -> 24750 | N17: =SUM(B17:M17) -> 276750
A18: Ballenita | B18: =(280)*(5*30) -> 42000 | C18: =(280)*(5*30) -> 42000 | D18: =(280)*(5*30) -> 42000 | E18: =(280)*(5*30) -> 42000 | F18: =(280)*(5*30) -> 42000 | G18: =(280)*(5*30) -> 42000 | H18: =(280)*(5*30) -> 42000 | I18: =(280)*(5*30) -> 42000 | ... M18: =(280)*(5*30) -> 42000 | N18: =SUM(B18:M18) -> 504000
A19: Norteño | B19: =(240)*(5*30) -> 36000 | C19: =(240)*(5*30) -> 36000 | D19: =(240)*(5*30) -> 36000 | E19: =(240)*(5*30) -> 36000 | F19: =(240)*(5*30) -> 36000 | G19: =(240)*(5*30) -> 36000 | H19: =(240)*(5*30) -> 36000 | I19: =(240)*(5*30) -> 36000 | ... M19: =(240)*(5*30) -> 36000 | N19: =SUM(B19:M19) -> 432000
A20: Taco de Suadero | B20: =(16)*(50*30) -> 24000 | C20: =(16)*(50*30) -> 24000 | D20: =(16)*(50*30) -> 24000 | E20: =(16)*(52*30) -> 24960 | F20: =(16)*(52*30) -> 24960 | G20: =(16)*(52*30) -> 24960 | H20: =(16)*(54*30) -> 25920 | I20: =(16)*(54*30) -> 25920 | J20: =(16)*(54*30) -> 25920 | K20: =(16)*(56*30) -> 26880 | L20: =(16)*(56*30) -> 26880 | M20: =(16)*(56*30) -> 26880 | N20: =SUM(B20:M20) -> 305280
A21: Tacos de Bistec | B21: =(16)*(50*30) -> 24000 | C21: =(16)*(50*30) -> 24000 | D21: =(16)*(50*30) -> 24000 | E21: =(16)*(52*30) -> 24960 | F21: =(16)*(52*30) -> 24960 | G21: =(16)*(52*30) -> 24960 | H21: =(16)*(54*30) -> 25920 | I21: =(16)*(54*30) -> 25920 | J21: =(16)*(54*30) -> 25920 | K21: =(16)*(56*30) -> 26880 | L21: =(16)*(56*30) -> 26880 | M21: =(16)*(56*30) -> 26880 | N21: =SUM(B21:M21) -> 305280
A22: Tacos de Cabeza | B22: =(16)*(45*30) -> 21600 | C22: =(16)*(45*30) -> 21600 | D22: =(16)*(45*30) -> 21600 | E22: =(16)*(47*30) -> 22560 | F22: =(16)*(47*30) -> 22560 | G22: =(16)*(47*30) -> 22560 | H22: =(16)*(49*30) -> 23520 | I22: =(16)*(49*30) -> 23520 | J22: =(16)*(49*30) -> 23520 | K22: =(16)*(51*30) -> 24480 | L22: =(16)*(51*30) -> 24480 | M22: =(16)*(51*30) -> 24480 | N22: =SUM(B22:M22) -> 276480
A23: Taco de Maciza | B23: =(16)*(70*30) -> 33600 | C23: =(16)*(70*30) -> 33600 | D23: =(16)*(70*30) -> 33600 | E23: =(16)*(72*30) -> 34560 | F23: =(16)*(72*30) -> 34560 | G23: =(16)*(72*30) -> 34560 | H23: =(16)*(75*30) -> 36000 | I23: =(16)*(75*30) -> 36000 | J23: =(16)*(75*30) -> 36000 | K23: =(16)*(78*30) -> 37440 | L23: =(16)*(78*30) -> 37440 | M23: =(16)*(78*30) -> 37440 | N23: =SUM(B23:M23) -> 424800
A24: TOTAL DE INGRESOS | B24: =SUM(B11:B23) -> 1202850 | C24: =SUM(C11:C23) -> 1202850 | D24: =SUM(D11:D23) -> 1202850 | E24: =SUM(E11:E23) -> 1239090 | F24: =SUM(F11:F23) -> 1239090 | G24: =SUM(G11:G23) -> 1239090 | H24: =SUM(H11:H23) -> 1278360 | I24: =SUM(I11:I23) -> 1278360 | ... M24: =SUM(M11:M23) -> 1320810 | N24: =SUM(B24:M24) -> 15123330
A28: CONCEPTOS | B28: INGRESOS POR VENTA MENSUAL AÑO 2
A29: MES | B29: 1 | C29: 2 | D29: 3 | E29: 4 | F29: 5 | G29: 6 | H29: 7 | I29: 8 | J29: 9 | K29: 10 | L29: 11 | M29: 12 | N29: TOTAL
A30: Productos del local | N30: ANUAL
A31: Tacos al pastor | B31: =$Q$69*(438*30) -> 229161.6 | C31: =$Q$69*(438*30) -> 229161.6 | D31: =$Q$69*(438*30) -> 229161.6 | E31: =$Q$69*(438*30) -> 229161.6 | F31: =$Q$69*(438*30) -> 229161.6 | G31: =$Q$69*(438*30) -> 229161.6 | H31: =$Q$69*(438*30) -> 229161.6 | I31: =$Q$69*(438*30) -> 229161.6 | ... M31: =$Q$69*(438*30) -> 229161.6 | N31: =SUM(B31:M31) -> 2749939.2
A32: Taco arabe gigante | B32: =$Q$70*(143*30) -> 467610 | C32: =$Q$70*(143*30) -> 467610 | D32: =$Q$70*(143*30) -> 467610 | E32: =$Q$70*(143*30) -> 467610 | F32: =$Q$70*(143*30) -> 467610 | G32: =$Q$70*(143*30) -> 467610 | H32: =$Q$70*(143*30) -> 467610 | I32: =$Q$70*(143*30) -> 467610 | ... M32: =$Q$70*(143*30) -> 467610 | N32: =SUM(B32:M32) -> 5611320
A33: Matahambre | B33: =($Q$71)*(56*30) -> 402864 | C33: =($Q$71)*(56*30) -> 402864 | D33: =($Q$71)*(56*30) -> 402864 | E33: =($Q$71)*(56*30) -> 402864 | F33: =($Q$71)*(56*30) -> 402864 | G33: =($Q$71)*(56*30) -> 402864 | H33: =($Q$71)*(56*30) -> 402864 | I33: =($Q$71)*(56*30) -> 402864 | ... M33: =($Q$71)*(56*30) -> 402864 | N33: =SUM(B33:M33) -> 4834368
A34: 1 litro de agua de horchata | B34: =($Q$72)*(303*4) -> 59448.6 | C34: =($Q$72)*(303*4) -> 59448.6 | D34: =($Q$72)*(303*4) -> 59448.6 | E34: =($Q$72)*(303*4) -> 59448.6 | F34: =($Q$72)*(303*4) -> 59448.6 | G34: =($Q$72)*(303*4) -> 59448.6 | H34: =($Q$72)*(303*4) -> 59448.6 | I34: =($Q$72)*(303*4) -> 59448.6 | ... M34: =($Q$72)*(303*4) -> 59448.6 | N34: =SUM(B34:M34) -> 713383.2
A35: Una tazas de cafe americano | B35: =($Q$73)*(5*30) -> 3270 | C35: =($Q$73)*(5*30) -> 3270 | D35: =($Q$73)*(5*30) -> 3270 | E35: =($Q$73)*(5*30) -> 3270 | F35: =($Q$73)*(5*30) -> 3270 | G35: =($Q$73)*(5*30) -> 3270 | H35: =($Q$73)*(5*30) -> 3270 | I35: =($Q$73)*(5*30) -> 3270 | ... M35: =($Q$73)*(5*30) -> 3270 | N35: =SUM(B35:M35) -> 39240
A36: Tortas hawaiana | B36: =($Q$74)*(16*30) -> 39240 | C36: =($Q$74)*(16*30) -> 39240 | D36: =($Q$74)*(16*30) -> 39240 | E36: =($Q$74)*(16*30) -> 39240 | F36: =($Q$74)*(16*30) -> 39240 | G36: =($Q$74)*(16*30) -> 39240 | H36: =($Q$74)*(16*30) -> 39240 | I36: =($Q$74)*(16*30) -> 39240 | ... M36: =($Q$74)*(16*30) -> 39240 | N36: =SUM(B36:M36) -> 470880
A37: Hamburguesa Hawaiana | B37: =($Q$75)*(11*30) -> 26977.5 | C37: =($Q$75)*(11*30) -> 26977.5 | D37: =($Q$75)*(11*30) -> 26977.5 | E37: =($Q$75)*(11*30) -> 26977.5 | F37: =($Q$75)*(11*30) -> 26977.5 | G37: =($Q$75)*(11*30) -> 26977.5 | H37: =($Q$75)*(11*30) -> 26977.5 | I37: =($Q$75)*(11*30) -> 26977.5 | ... M37: =($Q$75)*(11*30) -> 26977.5 | N37: =SUM(B37:M37) -> 323730
A38: Ballenita | B38: =($Q$76)*(5*30) -> 45780 | C38: =($Q$76)*(5*30) -> 45780 | D38: =($Q$76)*(5*30) -> 45780 | E38: =($Q$76)*(5*30) -> 45780 | F38: =($Q$76)*(5*30) -> 45780 | G38: =($Q$76)*(5*30) -> 45780 | H38: =($Q$76)*(5*30) -> 45780 | I38: =($Q$76)*(5*30) -> 45780 | ... M38: =($Q$76)*(5*30) -> 45780 | N38: =SUM(B38:M38) -> 549360
A39: Norteño | B39: =($Q$77)*(5*30) -> 39240 | C39: =($Q$77)*(5*30) -> 39240 | D39: =($Q$77)*(5*30) -> 39240 | E39: =($Q$77)*(5*30) -> 39240 | F39: =($Q$77)*(5*30) -> 39240 | G39: =($Q$77)*(5*30) -> 39240 | H39: =($Q$77)*(5*30) -> 39240 | I39: =($Q$77)*(5*30) -> 39240 | ... M39: =($Q$77)*(5*30) -> 39240 | N39: =SUM(B39:M39) -> 470880
A40: Taco de Suadero | B40: =($Q$78)*(56*30) -> 29299.2 | C40: =($Q$78)*(56*30) -> 29299.2 | D40: =($Q$78)*(56*30) -> 29299.2 | E40: =($Q$78)*(56*30) -> 29299.2 | F40: =($Q$78)*(56*30) -> 29299.2 | G40: =($Q$78)*(56*30) -> 29299.2 | H40: =($Q$78)*(56*30) -> 29299.2 | I40: =($Q$78)*(56*30) -> 29299.2 | ... M40: =($Q$78)*(56*30) -> 29299.2 | N40: =SUM(B40:M40) -> 351590.4
A41: Tacos de Bistec | B41: =($Q$79)*(56*30) -> 29299.2 | C41: =($Q$79)*(56*30) -> 29299.2 | D41: =($Q$79)*(56*30) -> 29299.2 | E41: =($Q$79)*(56*30) -> 29299.2 | F41: =($Q$79)*(56*30) -> 29299.2 | G41: =($Q$79)*(56*30) -> 29299.2 | H41: =($Q$79)*(56*30) -> 29299.2 | I41: =($Q$79)*(56*30) -> 29299.2 | ... M41: =($Q$79)*(56*30) -> 29299.2 | N41: =SUM(B41:M41) -> 351590.4
